 <!--
 MuJoCo MJCF test file. See http://mujoco.org/book/index.html
  -->
<mujoco>
      <compiler inertiafromgeom="true"/>
      <!-- <option gravity='0 0 -9.81' timestep='0.01'/> -->
      <worldbody>
      <!-- <light diffuse=".5 .5 .5" pos="0 0 3" dir="0 0 -1"/>     -->
      <!-- <geom type="plane" size="1 1 0.1" rgba=".9 0 0 1"/> -->
      <body pos="0 0 0">
         <joint type="slide" axis="1 0 0"/>
         <joint type="slide" axis="0 0 1"/>
         <!-- <joint type="slide" axis="0 1 0"/> -->
         <joint type="hinge" axis="0 1 0"/>
         <geom name="aux_1_geom" size="0.07 0.015" type="cylinder"/>
      </body>
      </worldbody>
</mujoco>
