<?xml version="1.0"?>
<robot name="balance">

    <material name="white">
    <color rgba="1 1 1 1"/>
    </material>

    <material name="black">
    <color rgba="0.2 0.2 0.2 1"/>
    </material>

    <material name="blue">
    <color rgba="0 0 1 1"/>
    </material>

    <link name="world">
        <inertial>
            <mass value="0"/>
            <inertia ixx="0.00016" ixy="0" ixz="0" iyy="0.00016" iyz="0" izz="0.00032"/>
            <origin rpy="0 0 0" xyz="0 0 0"/>
        </inertial>
    </link>

	<link name="x_prismatic">
        <inertial>
            <mass value="0.1"/>
            <inertia ixx="0.00016" ixy="0" ixz="0" iyy="0.00016" iyz="0" izz="0.00032"/>
            <origin rpy="0 0 0" xyz="0 0 0"/>
        </inertial>
	</link>

    <joint name="x_to_world" type="prismatic">
        <parent link="world"/>
        <child link="x_prismatic"/>
        <axis xyz="1 0 0"/>
        <limit effort="0.0" lower="5" upper="-5" velocity="1000.0"/>
        <origin rpy="0 0 0" xyz="0 0 0"/>
    </joint>

    <link name="z_prismatic">
        <inertial>
            <mass value="0.1"/>
            <inertia ixx="0.00016" ixy="0" ixz="0" iyy="0.00016" iyz="0" izz="0.00032"/>
            <origin rpy="0 0 0" xyz="0 0 0"/>
        </inertial>
    </link>

    <joint name="z_to_x" type="prismatic">
        <parent link="x_prismatic"/>
        <child link="z_prismatic"/>
        <axis xyz="0 0 1"/>
        <limit effort="0.0" lower="5" upper="-5" velocity="1000.0"/>
        <origin rpy="0 0 0" xyz="0 0 0"/>
    </joint>

    <joint name="torso_to_z" type="continuous">
        <parent link="z_prismatic"/>
        <child link="torso"/>
        <axis xyz="0 1 0"/>
        <origin rpy="0 0 0" xyz="0 0 0"/>
    </joint>

    <link name="torso">
        <visual>
            <geometry>
                <cylinder radius="0.08" length="0.02"/>
            </geometry>
            <origin rpy="0 0 0" xyz="0 0.0 0"/>
            <material name="white"/>
        </visual>
        <collision>
            <geometry>
                <cylinder radius="0.08" length="0.02"/>
            </geometry>
          <origin rpy="0 0 0" xyz="0 0.0 0"/>
          <!-- <contact_coefficients mu="0.08" /> -->
        </collision>
        <inertial>
            <mass value="0.1"/>
            <inertia ixx="0.00016" ixy="0" ixz="0" iyy="0.00016" iyz="0" izz="0.00032"/>
            <origin rpy="0 0 0" xyz="0 0.0 0"/>
        </inertial>
        <!-- <contact>
          <restitution value="0.0" />
          <rolling_friction value="0.01"/>
          <spinning_friction value="0.01"/>
        </contact> -->
    </link>



</robot>
